Workbook

Sheet ventas
A1: id | B1: id_cliente | C1: id_vendedor | D1: dte | E1: total_dte | F1: estado | G1: descripcion
A2: 1 | B2: 191 | C2: 15 | D2: 10001 | E2: 650631 | F2: Entregado | G2: 2x Disco Duro Externo 2TB, 3x Mouse Ergonómico Inalámbrico, 2x Silla de Escritorio Ergonómica, 1x Escáner de Documentos Portátil
A3: 2 | B3: 109 | C3: 3 | D3: 10004 | E3: 903198 | F3: Entregado | G3: 2x Escáner de Documentos Portátil, 1x Mouse Ergonómico Inalámbrico, 1x Auriculares con Micrófono USB, 2x Impresora Láser Multifuncional
A4: 3 | B4: 76 | C4: 10 | D4: 10007 | E4: 231213 | F4: Entregado | G4: 2x Escáner de Documentos Portátil, 2x Memoria RAM 16GB DDR4, 1x Mouse Ergonómico Inalámbrico, 3x Silla de Escritorio Ergonómica
A5: 4 | B5: 158 | C5: 14 | D5: 10009 | E5: 752982 | F5: Sin entregar | G5: 3x Licencia Software Antivirus 1 Año, 3x Laptop Corporate 14', 2x Monitor LED 24' Full HD
A6: 5 | B6: 132 | C6: 6 | D6: 10011 | E6: 36388 | F6: Entregado | G6: 3x Mouse Ergonómico Inalámbrico
A7: 6 | B7: 201 | C7: 15 | D7: 10014 | E7: 706762 | F7: Entregado | G7: 1x Mouse Ergonómico Inalámbrico
A8: 7 | B8: 200 | C8: 12 | D8: 10015 | E8: 319835 | F8: Entregado | G8: 3x Memoria RAM 16GB DDR4, 1x Escáner de Documentos Portátil, 3x Laptop Corporate 14'
A9: 8 | B9: 243 | C9: 12 | D9: 10017 | E9: 306798 | F9: Entregado | G9: 1x Silla de Escritorio Ergonómica, 3x Monitor LED 24' Full HD, 2x Escáner de Documentos Portátil
A10: 9 | B10: 81 | C10: 9 | D10: 10019 | E10: 444584 | F10: Entregado | G10: 3x Monitor LED 24' Full HD, 1x Laptop Corporate 14'
A11: 10 | B11: 133 | C11: 13 | D11: 10021 | E11: 30402 | F11: Sin entregar | G11: 2x Impresora Láser Multifuncional
A12: 11 | B12: 115 | C12: 7 | D12: 10024 | E12: 145013 | F12: Entregado | G12: 1x Hub USB-C 8 en 1, 1x Silla de Escritorio Ergonómica, 1x Teclado Mecánico RGB
A13: 12 | B13: 45 | C13: 15 | D13: 10026 | E13: 176461 | F13: Entregado | G13: 2x Licencia Software Antivirus 1 Año
... A1201: 1200 | B1201: 101 | C1201: 4 | D1201: 12414 | E1201: 685750 | F1201: Entregado | G1201: 3x Laptop Corporate 14', 1x Memoria RAM 16GB DDR4, 1x Monitor LED 24' Full HD, 3x Silla de Escritorio Ergonómica

Sheet ventas_100
A1: id | B1: id_cliente | C1: id_vendedor | D1: dte | E1: total_dte | F1: estado | G1: descripcion | H1: nombre_cliente | I1: apellido_cliente | J1: id_cargo | K1: nombre_cargo | L1: id_area | M1: nombre_area | N1: Categoria_Ticket | O1: =AVERAGE(E:E) -> 449665.24
A2: 1 | B2: 191 | C2: 15 | D2: 10001 | E2: 650631 | F2: Entregado | G2: 2x Disco Duro Externo 2TB, 3x Mouse Ergonómico Inalámbrico, 2x Silla de Escritorio Ergonómica, 1x Escáner de Documentos Portátil | H2: {=XLOOKUP(B2, clientes!A:A, clientes!C:C)} -> Jorge | I2: {=XLOOKUP(B2, clientes!A:A, clientes!E:E)} -> Vergara | J2: {=XLOOKUP(C2, trabajadores!A:A, trabajadores!B:B)} -> 3 | K2: {=XLOOKUP(J2, cargos!A:A, cargos!B:B)} -> Ejecutivo de Ventas Junior | L2: {=XLOOKUP(J2, cargos!A:A, cargos!D:D)} -> 1 | M2: {=XLOOKUP(L2, areas!A:A, areas!B:B)} -> Ventas y Comercial | N2: =IF(E2>1,"Ticket alto","Ticket Bajo") -> Ticket alto
A3: 2 | B3: 109 | C3: 3 | D3: 10004 | E3: 903198 | F3: Entregado | G3: 2x Escáner de Documentos Portátil, 1x Mouse Ergonómico Inalámbrico, 1x Auriculares con Micrófono USB, 2x Impresora Láser Multifuncional | H3: {=XLOOKUP(B3, clientes!A:A, clientes!C:C)} -> José | I3: {=XLOOKUP(B3, clientes!A:A, clientes!E:E)} -> Garrido | J3: {=XLOOKUP(C3, trabajadores!A:A, trabajadores!B:B)} -> 2 | K3: {=XLOOKUP(J3, cargos!A:A, cargos!B:B)} -> Ejecutivo de Ventas Senior | L3: {=XLOOKUP(J3, cargos!A:A, cargos!D:D)} -> 1 | M3: {=XLOOKUP(L3, areas!A:A, areas!B:B)} -> Ventas y Comercial | N3: =IF(E3>1,"Ticket alto","Ticket Bajo") -> Ticket alto
A4: 3 | B4: 76 | C4: 10 | D4: 10007 | E4: 231213 | F4: Entregado | G4: 2x Escáner de Documentos Portátil, 2x Memoria RAM 16GB DDR4, 1x Mouse Ergonómico Inalámbrico, 3x Silla de Escritorio Ergonómica | H4: {=XLOOKUP(B4, clientes!A:A, clientes!C:C)} -> Matías | I4: {=XLOOKUP(B4, clientes!A:A, clientes!E:E)} -> Fuentes | J4: {=XLOOKUP(C4, trabajadores!A:A, trabajadores!B:B)} -> 3 | K4: {=XLOOKUP(J4, cargos!A:A, cargos!B:B)} -> Ejecutivo de Ventas Junior | L4: {=XLOOKUP(J4, cargos!A:A, cargos!D:D)} -> 1 | M4: {=XLOOKUP(L4, areas!A:A, areas!B:B)} -> Ventas y Comercial | N4: =IF(E4>1,"Ticket alto","Ticket Bajo") -> Ticket alto
A5: 4 | B5: 158 | C5: 14 | D5: 10009 | E5: 752982 | F5: Sin entregar | G5: 3x Licencia Software Antivirus 1 Año, 3x Laptop Corporate 14', 2x Monitor LED 24' Full HD | H5: {=XLOOKUP(B5, clientes!A:A, clientes!C:C)} -> Javiera | I5: {=XLOOKUP(B5, clientes!A:A, clientes!E:E)} -> Muñoz | J5: {=XLOOKUP(C5, trabajadores!A:A, trabajadores!B:B)} -> 3 | K5: {=XLOOKUP(J5, cargos!A:A, cargos!B:B)} -> Ejecutivo de Ventas Junior | L5: {=XLOOKUP(J5, cargos!A:A, cargos!D:D)} -> 1 | M5: {=XLOOKUP(L5, areas!A:A, areas!B:B)} -> Ventas y Comercial | N5: =IF(E5>1,"Ticket alto","Ticket Bajo") -> Ticket alto
A6: 5 | B6: 132 | C6: 6 | D6: 10011 | E6: 36388 | F6: Entregado | G6: 3x Mouse Ergonómico Inalámbrico | H6: {=XLOOKUP(B6, clientes!A:A, clientes!C:C)} -> Javiera | I6: {=XLOOKUP(B6, clientes!A:A, clientes!E:E)} -> Castro | J6: {=XLOOKUP(C6, trabajadores!A:A, trabajadores!B:B)} -> 2 | K6: {=XLOOKUP(J6, cargos!A:A, cargos!B:B)} -> Ejecutivo de Ventas Senior | L6: {=XLOOKUP(J6, cargos!A:A, cargos!D:D)} -> 1 | M6: {=XLOOKUP(L6, areas!A:A, areas!B:B)} -> Ventas y Comercial | N6: =IF(E6>1,"Ticket alto","Ticket Bajo") -> Ticket alto
A7: 6 | B7: 201 | C7: 15 | D7: 10014 | E7: 706762 | F7: Entregado | G7: 1x Mouse Ergonómico Inalámbrico | H7: {=XLOOKUP(B7, clientes!A:A, clientes!C:C)} -> Nicolás | I7: {=XLOOKUP(B7, clientes!A:A, clientes!E:E)} -> Medina | J7: {=XLOOKUP(C7, trabajadores!A:A, trabajadores!B:B)} -> 3 | K7: {=XLOOKUP(J7, cargos!A:A, cargos!B:B)} -> Ejecutivo de Ventas Junior | L7: {=XLOOKUP(J7, cargos!A:A, cargos!D:D)} -> 1 | M7: {=XLOOKUP(L7, areas!A:A, areas!B:B)} -> Ventas y Comercial | N7: =IF(E7>1,"Ticket alto","Ticket Bajo") -> Ticket alto
A8: 7 | B8: 200 | C8: 12 | D8: 10015 | E8: 319835 | F8: Entregado | G8: 3x Memoria RAM 16GB DDR4, 1x Escáner de Documentos Portátil, 3x Laptop Corporate 14' | H8: {=XLOOKUP(B8, clientes!A:A, clientes!C:C)} -> Patricia | I8: {=XLOOKUP(B8, clientes!A:A, clientes!E:E)} -> Díaz | J8: {=XLOOKUP(C8, trabajadores!A:A, trabajadores!B:B)} -> 2 | K8: {=XLOOKUP(J8, cargos!A:A, cargos!B:B)} -> Ejecutivo de Ventas Senior | L8: {=XLOOKUP(J8, cargos!A:A, cargos!D:D)} -> 1 | M8: {=XLOOKUP(L8, areas!A:A, areas!B:B)} -> Ventas y Comercial | N8: =IF(E8>1,"Ticket alto","Ticket Bajo") -> Ticket alto
A9: 8 | B9: 243 | C9: 12 | D9: 10017 | E9: 306798 | F9: Entregado | G9: 1x Silla de Escritorio Ergonómica, 3x Monitor LED 24' Full HD, 2x Escáner de Documentos Portátil | H9: {=XLOOKUP(B9, clientes!A:A, clientes!C:C)} -> Alejandro | I9: {=XLOOKUP(B9, clientes!A:A, clientes!E:E)} -> Muñoz | J9: {=XLOOKUP(C9, trabajadores!A:A, trabajadores!B:B)} -> 2 | K9: {=XLOOKUP(J9, cargos!A:A, cargos!B:B)} -> Ejecutivo de Ventas Senior | L9: {=XLOOKUP(J9, cargos!A:A, cargos!D:D)} -> 1 | M9: {=XLOOKUP(L9, areas!A:A, areas!B:B)} -> Ventas y Comercial | N9: =IF(E9>1,"Ticket alto","Ticket Bajo") -> Ticket alto
A10: 9 | B10: 81 | C10: 9 | D10: 10019 | E10: 444584 | F10: Entregado | G10: 3x Monitor LED 24' Full HD, 1x Laptop Corporate 14' | H10: {=XLOOKUP(B10, clientes!A:A, clientes!C:C)} -> Natalia | I10: {=XLOOKUP(B10, clientes!A:A, clientes!E:E)} -> Valenzuela | J10: {=XLOOKUP(C10, trabajadores!A:A, trabajadores!B:B)} -> 3 | K10: {=XLOOKUP(J10, cargos!A:A, cargos!B:B)} -> Ejecutivo de Ventas Junior | L10: {=XLOOKUP(J10, cargos!A:A, cargos!D:D)} -> 1 | M10: {=XLOOKUP(L10, areas!A:A, areas!B:B)} -> Ventas y Comercial | N10: =IF(E10>1,"Ticket alto","Ticket Bajo") -> Ticket alto
A11: 10 | B11: 133 | C11: 13 | D11: 10021 | E11: 30402 | F11: Sin entregar | G11: 2x Impresora Láser Multifuncional | H11: {=XLOOKUP(B11, clientes!A:A, clientes!C:C)} -> Francisca | I11: {=XLOOKUP(B11, clientes!A:A, clientes!E:E)} -> Torres | J11: {=XLOOKUP(C11, trabajadores!A:A, trabajadores!B:B)} -> 2 | K11: {=XLOOKUP(J11, cargos!A:A, cargos!B:B)} -> Ejecutivo de Ventas Senior | L11: {=XLOOKUP(J11, cargos!A:A, cargos!D:D)} -> 1 | M11: {=XLOOKUP(L11, areas!A:A, areas!B:B)} -> Ventas y Comercial | N11: =IF(E11>1,"Ticket alto","Ticket Bajo") -> Ticket alto
A12: 11 | B12: 115 | C12: 7 | D12: 10024 | E12: 145013 | F12: Entregado | G12: 1x Hub USB-C 8 en 1, 1x Silla de Escritorio Ergonómica, 1x Teclado Mecánico RGB | H12: {=XLOOKUP(B12, clientes!A:A, clientes!C:C)} -> Natalia | I12: {=XLOOKUP(B12, clientes!A:A, clientes!E:E)} -> Morales | J12: {=XLOOKUP(C12, trabajadores!A:A, trabajadores!B:B)} -> 2 | K12: {=XLOOKUP(J12, cargos!A:A, cargos!B:B)} -> Ejecutivo de Ventas Senior | L12: {=XLOOKUP(J12, cargos!A:A, cargos!D:D)} -> 1 | M12: {=XLOOKUP(L12, areas!A:A, areas!B:B)} -> Ventas y Comercial | N12: =IF(E12>1,"Ticket alto","Ticket Bajo") -> Ticket alto
A13: 12 | B13: 45 | C13: 15 | D13: 10026 | E13: 176461 | F13: Entregado | G13: 2x Licencia Software Antivirus 1 Año | H13: {=XLOOKUP(B13, clientes!A:A, clientes!C:C)} -> Nicole | I13: {=XLOOKUP(B13, clientes!A:A, clientes!E:E)} -> Díaz | J13: {=XLOOKUP(C13, trabajadores!A:A, trabajadores!B:B)} -> 3 | K13: {=XLOOKUP(J13, cargos!A:A, cargos!B:B)} -> Ejecutivo de Ventas Junior | L13: {=XLOOKUP(J13, cargos!A:A, cargos!D:D)} -> 1 | M13: {=XLOOKUP(L13, areas!A:A, areas!B:B)} -> Ventas y Comercial | N13: =IF(E13>1,"Ticket alto","Ticket Bajo") -> Ticket alto
... A101: 100 | B101: 71 | C101: 33 | D101: 10218 | E101: 339855 | F101: Entregado | G101: 1x Laptop Corporate 14', 1x Auriculares con Micrófono USB, 1x Memoria RAM 16GB DDR4 | H101: {=XLOOKUP(B101, clientes!A:A, clientes!C:C)} -> Francisca | I101: {=XLOOKUP(B101, clientes!A:A, clientes!E:E)} -> Soto | J101: {=XLOOKUP(C101, trabajadores!A:A, trabajadores!B:B)} -> 1 | K101: {=XLOOKUP(J101, cargos!A:A, cargos!B:B)} -> Gerente Comercial | L101: {=XLOOKUP(J101, cargos!A:A, cargos!D:D)} -> 1 | M101: {=XLOOKUP(L101, areas!A:A, areas!B:B)} -> Ventas y Comercial | N101: =IF(E101>1,"Ticket alto","Ticket Bajo") -> Ticket alto

Sheet Tabla dinámica 1

Sheet clientes
A1: id | B1: rut | C1: nombre | D1: segundo_nombre | E1: apellido | F1: segundo_apellido | G1: edad | H1: fecha_nacimiento
A2: 1 | B2: 12154051-7 | C2: Carlos | D2: Javier | E2: Medina | F2: Rojas | G2: 55 | H2: 26036
A3: 2 | B3: 13553384-K | C3: Bárbara | D3: Carolina | E3: Martínez | F3: Valenzuela | G3: 29 | H3: 35781
A4: 3 | B4: 17350099-8 | C4: Rodrigo | D4: Alejandro | E4: Vergara | F4: Araya | G4: 33 | H4: 34152
A5: 4 | B5: 10352896-8 | C5: Javiera | D5: Valentina | E5: Silva | F5: Rojas | G5: 36 | H5: 32994
A6: 5 | B6: 13841005-6 | C6: Matías | D6: Manuel | E6: González | F6: Rojas | G6: 61 | H6: 23845
A7: 6 | B7: 14672073-0 | C7: José | D7: Gonzalo | E7: Rojas | F7: Valenzuela | G7: 45 | H7: 29714
A8: 7 | B8: 14076817-0 | C8: Daniela | D8: Bárbara | E8: Pérez | F8: Donoso | G8: 24 | H8: 37404
A9: 8 | B9: 15944126-1 | C9: Patricia | D9: Daniela | E9: Díaz | F9: Díaz | G9: 28 | H9: 36040
A10: 9 | B10: 21297182-0 | C10: Patricia | D10: Alejandra | E10: Cortés | F10: Donoso | G10: 60 | H10: 23691
A11: 10 | B11: 14171761-8 | C11: José | D11: Alejandro | E11: Donoso | F11: Morales | G11: 57 | H11: 25496
A12: 11 | B12: 13078418-6 | C12: Francisco | D12: Felipe | E12: Fuentes | F12: Pérez | G12: 29 | H12: 35740
A13: 12 | B13: 17434500-7 | C13: Alejandra | D13: Valentina | E13: Cortés | F13: Castro | G13: 60 | H13: 24386
... A67: 66 | B67: 19658481-1 | C67: Francisco | D67: Cristián | E67: Herrera | F67: Espinoza | G67: 65 | H67: 22556
A68: 67 | B68: 17030010-6 | C68: Sofía | D68: María | E68: Rodríguez | F68: Flores | H68: 34695
A69: 68 | B69: 10486955-6 | C69: Javier | D69: Manuel | E69: Martínez | F69: Sepúlveda | G69: 23 | H69: 37829
A70: 69 | B70: 12141239-K | C70: Andrea | D70: Claudia | E70: Donoso | F70: Soto | G70: 25 | H70: 37231
A71: 70 | B71: 11408404-2 | C71: Alejandro | D71: Matías | E71: Tapia | F71: Vergara | G71: 64 | H71: 22804
A72: 71 | B72: 16360307-1 | C72: Francisca | D72: Alejandra | E72: Soto | F72: Muñoz | G72: 43 | H72: 30440
A73: 72 | B73: 14668371-1 | C73: Daniela | D73: Alejandra | E73: Morales | F73: Morales | G73: 32 | H73: 34339
A74: 73 | B74: 15871360-8 | C74: Constanza | D74: Camila | E74: Torres | F74: González | G74: 62 | H74: 23622
A75: 74 | B75: 13344717-2 | C75: Carlos | D75: José | E75: Lara | F75: González | G75: 44 | H75: 30018
A76: 75 | B76: 21231655-5 | C76: Nicolás | D76: Pedro | E76: Silva | F76: Pérez | G76: 24 | H76: 37433
A77: 76 | B77: 16189034-0 | C77: Matías | D77: Francisco | E77: Fuentes | F77: Casanova | G77: 44 | H77: 30312
A78: 77 | B78: 12747534-2 | C78: Nicolás | D78: Nicolás | E78: Donoso | F78: Casanova | G78: 56 | H78: 25669
A79: 78 | B79: 19660266-6 | C79: Javiera | D79: Verónica | E79: González | F79: Castro | G79: 39 | H79: 32138
A80: 79 | B80: 11709620-3 | C80: Claudia | D80: Daniela | E80: Rojas | F80: Tapia | G80: 45 | H80: 29873
... A105: 104 | B105: 12626181-0 | C105: Diego | D105: Manuel | E105: Soto | F105: Castillo | G105: 60 | H105: 24375
A106: 105 | B106: 14886520-5 | C106: Cristián | D106: Marcelo | E106: Casanova | F106: Cárcamo | H106: 37314
A107: 106 | B107: 11194198-K | C107: Manuel | D107: Rodrigo | E107: Casanova | F107: Flores | G107: 26 | H107: 36793
A108: 107 | B108: 17132648-6 | C108: Jorge | D108: Matías | E108: Vergara | F108: Garrido | G108: 49 | H108: 28398
A109: 108 | B109: 12386328-3 | C109: Felipe | D109: Manuel | E109: Araya | F109: Pérez | G109: 43 | H109: 30620
A110: 109 | B110: 17367772-3 | C110: José | D110: Diego | E110: Garrido | F110: Flores | G110: 41 | H110: 31373
A111: 110 | B111: 18396529-8 | C111: Marcelo | D111: Rodrigo | E111: Casanova | F111: Herrera | G111: 42 | H111: 30836
A112: 111 | B112: 15407658-1 | C112: Alejandra | D112: Camila | E112: Cárcamo | F112: Muñoz | G112: 28 | H112: 36072
A113: 112 | B113: 21279013-3 | C113: María | D113: Camila | E113: Silva | F113: Vergara | G113: 65 | H113: 22595
A114: 113 | B114: 17893693-K | C114: Verónica | D114: Ana | E114: Lara | F114: Lara | G114: 51 | H114: 27656
A115: 114 | B115: 11530793-2 | C115: Constanza | D115: Carolina | E115: Tapia | F115: Sepúlveda | G115: 22 | H115: 38028
A116: 115 | B116: 12698193-7 | C116: Natalia | D116: Patricia | E116: Morales | F116: Morales | G116: 57 | H116: 25343
A117: 116 | B117: 19229089-9 | C117: Patricia | D117: Sofía | E117: Flores | F117: Vergara | G117: 31 | H117: 35038
...

Sheet trabajadores
A1: id | B1: id_cargo | C1: nombre | D1: apellido | E1: rut
A2: 1 | B2: 3 | C2: Juan | D2: Donoso | E2: 14108603-0
A3: 2 | B3: 2 | C3: Pedro | D3: Donoso | E3: 21353133-6
A4: 3 | B4: 2 | C4: Matías | D4: Sepúlveda | E4: 10499914-K
A5: 4 | B5: 2 | C5: Francisco | D5: Silva | E5: 19416129-8
A6: 5 | B6: 2 | C6: Felipe | D6: Sepúlveda | E6: 17536477-3
A7: 6 | B7: 2 | C7: María | D7: Lara | E7: 21712835-8
A8: 7 | B8: 2 | C8: Andrea | D8: Martínez | E8: 13612365-3
A9: 8 | B9: 3 | C9: Javiera | D9: Rojas | E9: 11622631-6
A10: 9 | B10: 3 | C10: Natalia | D10: Cárcamo | E10: 10728977-1
A11: 10 | B11: 3 | C11: Bárbara | D11: Díaz | E11: 11322047-3
A12: 11 | B12: 3 | C12: Nicole | D12: Espinoza | E12: 19686361-3
A13: 12 | B13: 2 | C13: Carlos | D13: Muñoz | E13: 14855124-3
... A36: 35 | B36: 6 | C36: Valentina | D36: Muñoz | E36: 19518669-3

Sheet cargos
A1: id | B1: nombre_cargo | C1: descripcion | D1: id_area
A2: 1 | B2: Gerente Comercial | C2: Liderar las estrategias de venta y cumplimiento de metas comerciales. | D2: 1
A3: 2 | B3: Ejecutivo de Ventas Senior | C3: Venta directa y gestión de grandes cuentas de clientes. | D3: 1
A4: 3 | B4: Ejecutivo de Ventas Junior | C4: Atención de prospectos y cierre de ventas de canal regular. | D4: 1
A5: 4 | B5: Jefe de Logística | C5: Coordinar la cadena de suministro y despacho a nivel nacional. | D5: 2
A6: 5 | B6: Operario de Bodega | C6: Preparación de pedidos, recepción de mercadería y orden. | D6: 2
A7: 6 | B7: Ingeniero de Soporte TI | C7: Resolver incidencias de hardware, software y redes. | D7: 3
A8: 7 | B8: Desarrollador Full Stack | C8: Mantenimiento y desarrollo de las plataformas de software de la empresa. | D8: 3
A9: 8 | B9: Analista de RRHH | C9: Procesamiento de remuneraciones, contratos y gestión interna. | D9: 4
A10: 9 | B10: Contador General | C10: Declaraciones de impuestos, balances comerciales y auditoría básica. | D10: 5
A11: 10 | B11: Analista Financiero | C11: Control de presupuestos, flujo de caja y relación con bancos. | D11: 5

Sheet areas
A1: id | B1: nombre_area | C1: descripcion
A2: 1 | B2: Ventas y Comercial | C2: Área encargada de la comercialización de productos y atención a clientes.
A3: 2 | B3: Operaciones y Logística | C3: Gestión de inventario, bodegaje y despacho de mercancías.
A4: 3 | B4: Tecnología y Soporte | C4: Mantenimiento de infraestructura tecnológica y soporte interno/externo.
A5: 4 | B5: Recursos Humanos | C5: Gestión del talento, contratación y bienestar de los trabajadores.
A6: 5 | B6: Finanzas y Contabilidad | C6: Administración de recursos financieros, facturación y contabilidad general.
